Workbook

Sheet Field Trials
A1: Trial ID | B1: Date | C1: Tester ID | D1: Route ID | E1: Start | F1: Destination | G1: Network | H1: Device / iOS | I1: Start time | J1: End time | K1: Actual minutes | L1: Valhalla ETA (min) | M1: Valhalla distance (m) | N1: Actual distance (m) | O1: Completed? | P1: GPS accuracy (m) | Q1: Wrong turns | R1: Entrance correct? | S1: Route line visible? | T1: Map loaded? | U1: Issues / observations | V1: Screenshot reference | W1: App version / commit
A2: 1 | B2: 46294 | C2: Diego | D2: 1 | E2: warr lect hall | F2: fah | G2: Hotspot | H2: Iphone | I2: 0.31527778 | J2: 0.32152778 | K2: =IF(OR(I2="",J2=""),"",MOD(J2-I2,1)*1440) -> 9 | L2: 9 | O2: Yes | Q2: 0 | R2: Yes | S2: Yes | T2: Yes
A3: 2 | B3: 46294 | C3: Diego | D3: 2 | E3: DIB | F3: Warren lecture hall | G3: UCSD Wi-Fi | H3: Iphone | I3: 0.33333333 | J3: 0.33611111 | K3: 3 | L3: 3 | M3: 915ft | N3: 0.15 | O3: Yes | Q3: 0 | R3: Yes | S3: Yes | T3: Yes
A4: 3 | B4: 46294 | C4: Diego | D4: 3 | E4: warr lect hall | F4: DIB | G4: Hotspot | H4: Iphone | I4: 0.3375 | J4: 0.33958333 | K4: =IF(OR(I4="",J4=""),"",MOD(J4-I4,1)*1440) -> 3 | L4: 3 | M4: 914ft | N4: 0.15 | O4: Yes | Q4: 0 | R4: Yes | S4: Yes | T4: Yes
A5: 4 | B5: 46294 | C5: Diego | D5: 4 | E5: warr lect hall | F5: Goldberg hall | G5: Hotspot | H5: Iphone | I5: 0.34722222 | J5: 0.34861111 | K5: =IF(OR(I5="",J5=""),"",MOD(J5-I5,1)*1440) -> 2 | L5: 1 | M5: 584ft | N5: 0.11 | O5: Yes | Q5: 0 | R5: Not tested | S5: Yes | T5: Yes
A6: 5 | B6: 46294 | C6: Diego | D6: 5 | E6: goldberg hall | F6: FAH | G6: Hotspot | H6: Iphone | I6: 0.35069444 | J6: 0.35138889 | K6: 4 | L6: 5 | M6: 0.1 | N6: 0.1 | O6: Yes | Q6: 0 | R6: Not tested | S6: Yes | T6: Yes
A7: 6 | B7: 46294 | C7: Diego | D7: 6 | E7: FAH | F7: Warren lecture hall | G7: Hotspot | H7: Iphone | I7: 0.35138889 | J7: 0.35486111 | K7: 5 | L7: 6 | M7: 0.3 | N7: 0.2 | O7: Yes | Q7: 0 | R7: Not tested | S7: Yes | T7: Yes
A8: 7 | B8: 46294 | C8: Diego | D8: 7 | E8: warr lect hall | F8: Geisel Library | G8: Hotspot | H8: Iphone | I8: 0.35486111 | J8: 0.35763889 | K8: 4 | L8: 5 | M8: 0.2 | N8: 0.2 | O8: Yes | Q8: 0 | R8: yy | S8: Yes | T8: Yes
A9: 8 | B9: 46294 | C9: Diego | D9: 8 | E9: Geisel Library | F9: Target | G9: Hotspot | H9: Iphone | I9: 0.35763889 | J9: 0.36180556 | K9: 4 | L9: 5 | M9: 0.2 | N9: 0.1 | O9: Yes | Q9: 1 | R9: Yes | S9: Yes | T9: Yes
A10: 9 | B10: 46294 | C10: Diego | D10: 9 | E10: Target | F10: Bird Rock Coffee | G10: Hotspot | H10: Iphone | I10: 0.36111111 | J10: 0.375 | K10: 20 | L10: 19 | M10: 0.3 | N10: 0.3 | O10: Yes | Q10: 1 | R10: Yes | S10: Yes | T10: Yes
A11: 10 | B11: 46294 | C11: Diego | D11: 10 | E11: DIB | F11: applied physics and mathematics | G11: Hotspot | H11: Iphone | I11: 0.37569444 | J11: 0.37916667 | K11: 5 | L11: 6 | M11: 0.6 | N11: 0.6 | O11: Yes | Q11: 1 | R11: Yes | S11: Yes | T11: Yes
A12: 11 | B12: 46295 | C12: Diego | D12: 11 | E12: applied physics and mathematics | F12: galbraith hall | G12: UCSD Wi-Fi | H12: Iphone | I12: 0.37916667 | J12: 0.3875 | K12: 12 | L12: 13 | M12: 0.6 | N12: 0.6 | O12: Yes | Q12: 1 | R12: Yes | S12: Yes | T12: Yes
A13: 12 | B13: 46295 | C13: Diego | D13: 12 | E13: galbraith hall | F13: MAIN gym | G13: UCSD Wi-Fi | H13: Iphone | I13: 0.3875 | J13: 0.39305556 | K13: 9 | L13: 11 | M13: 0.4m | N13: 0.3 | O13: Yes | Q13: 0 | R13: Yes | S13: Yes | T13: Yes
A14: 13 | B14: 46295 | C14: Diego | D14: 13 | E14: MAIN gym | F14: CSB building | G14: UCSD Wi-Fi | H14: Iphone | I14: 0.39305556 | J14: 0.39722222 | K14: 5 | L14: 6 | M14: 0.3 | N14: 0.3 | O14: Yes | Q14: 0 | R14: Yes | S14: Yes | T14: Yes
A15: 14 | B15: 46295 | C15: Diego | D15: 14 | E15: CSB building | F15: marshall college | G15: UCSD Wi-Fi | H15: Mac | K15: N/A | L15: N/A | M15: N/A | N15: N/A | O15: No | Q15: 0 | R15: N/A | S15: N/A | T15: Yes | U15: no route, returns college diagram
A16: 15 | B16: 46295 | C16: Diego | D16: 15 | E16: CSB building | F16: RIMAC | G16: UCSD Wi-Fi | H16: mac | I16: 0.40277778 | J16: 0.40833333 | K16: 8 | L16: 9 | M16: 0.5 | N16: 0.5 | O16: Yes | Q16: 0 | R16: Yes | S16: Yes | T16: Yes
A17: 16 | B17: 46295 | C17: Diego | D17: 16 | E17: RIMAC | F17: Seventh College Housing | G17: UCSD Wi-Fi | H17: Mac | I17: N/A | J17: N | K17: N/A | L17: N/A | M17: N/A | N17: N/A | O17: No | P17: N/A | Q17: 0 | R17: N/A | S17: No | T17: No | U17: no route, returns nothing
A18: 17 | B18: 46295 | C18: Diego | D18: 17 | E18: seventh college housing | F18: RIMAC | G18: UCSD Wi-Fi | H18: Iphone | I18: 0.41666667 | J18: 0.42222222 | K18: 8 | L18: 9 | M18: 1,273ft | N18: 0.2 | O18: Yes | Q18: 0 | R18: Yes | S18: Yes | T18: Yes
A19: 18 | B19: 46295 | C19: Diego | D19: 18 | E19: RIMAC | F19: Geisel Library | G19: UCSD Wi-Fi | H19: Iphone | I19: 0.42222222 | J19: 0.42638889 | K19: 6 | L19: 7 | M19: 0.4m | N19: 0.4 | O19: Yes | Q19: 0 | R19: Yes | S19: Yes | T19: Yes
A20: 19 | B20: 46295 | C20: Diego | D20: 19 | E20: Geisel Library | F20: CSB building | G20: UCSD Wi-Fi | H20: Iphone | I20: 0.42638889 | J20: 0.43194444 | K20: 8 | L20: 10 | M20: 0.5 | N20: 0.5 | O20: Yes | Q20: 0 | R20: Yes | S20: Yes | T20: Yes
A21: 20 | B21: 46295 | C21: Diego | D21: 20 | E21: CSB building | F21: Student Health and Wellness Center | G21: UCSD Wi-Fi | H21: Iphone | I21: 0.43194444 | J21: 0.43263889 | K21: 2 | L21: 2 | M21: 619ft | N21: 0.1 | O21: Yes | Q21: 0 | R21: Yes | S21: Yes | T21: Yes
A22: 21 | B22: 46295 | C22: Diego | D22: 21 | E22: Student Health and Wellness Center | F22: Mosaic Hall | G22: UCSD Wi-Fi | H22: Iphone | I22: 0.43263889 | J22: 0.43472222 | K22: 3 | L22: 4 | M22: 1,020ft | N22: 0.1 | O22: Yes | Q22: 0 | R22: Yes | S22: Yes | T22: Yes
A23: 22 | B23: 46295 | C23: Diego | D23: 22 | E23: Mosaic Hall | F23: catalyst | G23: UCSD Wi-Fi | H23: Iphone | I23: 0.43472222 | J23: 0.43541667 | K23: 1 | L23: 1 | M23: 207ft | N23: 0.1 | O23: Yes | Q23: 1 | R23: Yes | S23: Yes | T23: Yes
A24: 23 | B24: 46295 | C24: Diego | D24: 23 | E24: catalyst | F24: peterson hall | G24: UCSD Wi-Fi | H24: Iphone | I24: 0.43541667 | J24: 0.45833333 | K24: 4 | L24: 4 | M24: 1,138ft | N24: 0.2 | O24: Yes | Q24: 1 | R24: Yes | S24: Yes | T24: Yes
A25: 24 | B25: 46295 | C25: Diego | D25: 24 | E25: peterson hall | F25: sixth market | G25: UCSD Wi-Fi | H25: Iphone | I25: 0.45833333 | J25: 0.46111111 | K25: 4 | L25: 5 | M25: 0.2 | N25: 0.2 | O25: Yes | P25: not accurate | Q25: 1 | R25: Yes | S25: Yes | T25: Yes | U25: it depicts sixth market as being next to DIB, WRONG
A26: 25 | B26: 46295 | C26: Diego | D26: 25 | E26: peterson hall | F26: center hall | G26: UCSD Wi-Fi | H26: Iphone | I26: 0.46111111 | J26: 0.46597222 | K26: 7 | L26: 8 | M26: 0.4 | N26: 0.4 | O26: Yes | Q26: 0 | R26: Yes | S26: Yes | T26: Yes
A27: 25 | B27: 46295 | C27: Diego | D27: 26 | E27: center hall | F27: pepper canyon hall | G27: UCSD Wi-Fi | H27: Iphone | I27: N/A | J27: N/A | K27: N/A | L27: N/A | M27: N/A | N27: N/A | O27: Yes | P27: not accurate | Q27: 4 | R27: No | S27: Yes | T27: Yes | U27: it depits PCH at bonner hall
A28: 26 | B28: 46295 | C28: Diego | D28: 27 | E28: center hall | F28: MANDE | G28: UCSD Wi-Fi | H28: Iphone | I28: 0.46875 | J28: 0.47083333 | K28: 3 | L28: 7 | M28: 0.3 | N28: 0.1 | O28: Yes | Q28: 0 | R28: Yes | S28: Yes | T28: Yes
A29: 27 | B29: 46295 | C29: Diego | D29: 28 | E29: MANDE | F29: MAIN gym | G29: UCSD Wi-Fi | H29: Iphone | I29: 0.47083333 | J29: 0.47291667 | K29: 3 | L29: 3 | M29: 778ft | N29: 0.2 | O29: Yes | Q29: 0 | R29: Yes | S29: Yes | T29: Yes
A30: 28 | B30: 46295 | C30: Diego | D30: 29 | E30: MAIN gym | F30: FAH | G30: UCSD Wi-Fi | H30: Iphone | K30: =IF(OR(I30="",J30=""),"",MOD(J30-I30,1)*1440) | O30: Yes | Q30: 0 | R30: Yes | S30: Yes | T30: Yes
A31: 29 | B31: 46295 | C31: Diego | D31: 30 | E31: FAH | F31: center hall | G31: UCSD Wi-Fi | H31: Iphone | K31: =IF(OR(I31="",J31=""),"",MOD(J31-I31,1)*1440) | O31: Yes | Q31: 0 | R31: Yes | S31: Yes | T31: Yes
A32: 30 | B32: 46295 | C32: Diego | D32: 31 | E32: center hall | F32: Geisel Library | G32: UCSD Wi-Fi | H32: Iphone | K32: =IF(OR(I32="",J32=""),"",MOD(J32-I32,1)*1440) | O32: Yes | Q32: 0 | R32: Yes | S32: Yes | T32: Yes
A33: 31 | B33: 46295 | C33: Diego | D33: 32 | E33: Geisel Library | F33: galbraith hall | G33: UCSD Wi-Fi | H33: Iphone | K33: =IF(OR(I33="",J33=""),"",MOD(J33-I33,1)*1440) | O33: Yes | Q33: 0 | R33: Yes | S33: Yes | T33: Yes
A34: 32 | B34: 46295 | C34: Diego | D34: 33 | E34: galbraith hall | F34: fah | G34: UCSD Wi-Fi | H34: Iphone | K34: =IF(OR(I34="",J34=""),"",MOD(J34-I34,1)*1440) | O34: Yes | Q34: 0 | R34: Yes | S34: Yes | T34: Yes
A35: 33 | B35: 46295 | C35: Diego | D35: 34 | E35: fah | F35: DIB | G35: UCSD Wi-Fi | H35: Iphone | K35: =IF(OR(I35="",J35=""),"",MOD(J35-I35,1)*1440) | O35: Yes | Q35: 0 | R35: Yes | S35: Yes | T35: Yes
A36: 34 | B36: 46295 | C36: Diego | D36: 35 | E36: DIB | F36: Mosaic Hall | G36: UCSD Wi-Fi | H36: Iphone | K36: =IF(OR(I36="",J36=""),"",MOD(J36-I36,1)*1440) | O36: Yes | Q36: 0 | R36: Yes | S36: Yes | T36: Yes
A37: 35 | B37: 46295 | C37: Diego | D37: 36 | E37: Mosaic Hall | F37: center hall | G37: UCSD Wi-Fi | H37: Iphone | K37: =IF(OR(I37="",J37=""),"",MOD(J37-I37,1)*1440) | O37: Yes | Q37: 0 | R37: Yes | S37: Yes | T37: Yes
A38: 36 | B38: 46295 | C38: Diego | D38: 37 | E38: center hall | F38: DIB | G38: UCSD Wi-Fi | H38: Iphone | K38: =IF(OR(I38="",J38=""),"",MOD(J38-I38,1)*1440) | O38: Yes | Q38: 0 | R38: Yes | S38: Yes | T38: Yes
A39: 37 | B39: 46295 | C39: Diego | D39: 38 | E39: DIB | F39: MAIN gym | G39: UCSD Wi-Fi | H39: Iphone | K39: =IF(OR(I39="",J39=""),"",MOD(J39-I39,1)*1440) | O39: Yes | Q39: 0 | R39: Yes | S39: Yes | T39: Yes
A40: 38 | B40: 46295 | C40: Diego | D40: 39 | E40: MAIN gym | F40: Price Center | G40: UCSD Wi-Fi | H40: Iphone | K40: =IF(OR(I40="",J40=""),"",MOD(J40-I40,1)*1440) | O40: Yes | Q40: 0 | R40: Yes | S40: Yes | T40: Yes
...

Sheet Route Catalog
A1: Route ID | B1: Start | C1: Destination | D1: Route type | E1: Stairs / slope | F1: Entrances to verify | G1: Accessibility data status | H1: Priority | I1: Notes | J1: Verified on
A2: R01 | B2: Geisel Library | C2: Price Center | D2: Central campus | E2: Check on site | F2: Both endpoints | G2: Provisional | H2: High | I2: Baseline repeat route
A3: R02 | B3: Mandeville Center | C3: Sixth College | D3: Cross-campus | E3: Check on site | F3: Both endpoints | G3: Provisional | H3: High | I3: Longer navigation comparison
A4: R03 | B4: Price Center | C4: Warren College | D4: Cross-campus | E4: Check on site | F4: Both endpoints | G4: Provisional | H4: Medium | I4: Assess hill and crossing behavior
A5: R04 | B5: Geisel Library | C5: Revelle College | D5: Cross-campus | E5: Check on site | F5: Both endpoints | G5: Provisional | H5: Medium | I5: Assess distance and GPS drift
A6: R05 | B6: Marshall College | C6: Seventh College | D6: College-to-college | E6: Check on site | F6: Both endpoints | G6: Provisional | H6: Medium | I6: Verify actual walking access
A7: R06 | B7: Sixth College | C7: Eighth College | D7: College-to-college | E7: Check on site | F7: Both endpoints | G7: Provisional | H7: Medium | I7: Assess longer route and slope

Sheet Issue Log
A1: Issue ID | B1: Date | C1: Trial ID | D1: Area | E1: Severity | F1: Description | G1: Reproduction steps | H1: Status | I1: Screenshot / video | J1: Fix / retest notes

Sheet Research Dashboard
A1: TRITONNAV / FIELD STUDY DASHBOARD
A3: Metric | B3: Value
A4: Total trials | B4: =COUNTA('Field Trials'!A2:A301) -> 41
A5: Completed trials | B5: =COUNTIF('Field Trials'!O2:O301,"Yes") -> 40
A6: Completion rate | B6: =IFERROR(B5/B4,0) -> 0.97560976
A7: Average actual minutes | B7: =IFERROR(AVERAGE('Field Trials'!K2:K301),0) -> 5.68
A8: Average Valhalla ETA (min) | B8: =IFERROR(AVERAGE('Field Trials'!L2:L301),0) -> 6.44
A9: Logged issues | B9: =COUNTA('Issue Log'!A2:A201) -> 0
A11: RESEARCH NOTES
A12: Record every attempt, including failed trials.
A13: Use anonymous tester IDs; do not record names or precise personal location traces.
A14: Route Catalog entries are suggested tests, not verified accessibility routes.
